# 예외 처리(Exception)

## 1. 예외(exception)

- **실행 중인 프로그램에서 예기치 못한 상황이 발생하여 더 이상 진행할 수 없는 상황**
  - ex) 문법적인 오류이거나 파일을 찾을 수 없거나, 메모리 부족 등의 상황
- 예외 상황은 프로그램의 실행을 중단시키거나, 비정상적인 결과 초래할 수 있으므로, 발생한 예외를 처리할 수 있는 방법을 마련해야 함

<br><br>

## 2. 예외 처리(exception handling)

```jsx
try {
  lalala; // 변수가 정의되지 않았기 떄문에 에러 발생
} catch (err) {
  alert(err.name); // ReferenceError
  alert(err.message); // lalala is not defined
  alert(err.stack); // ReferenceError: lalala is not defined at ... (호출 스택)

  // 에러 전체를 보여줄 수 있음
  // 에러 객체는 "name: message" 형태의 문자열로 반환됨
  alert(err); // ReferenceError: lalala is not defined
} finally {
  // 무조건 실행되는 코드
}
```

<br><br>

## 3. try - catch - finally 문

### 3.1. try 문

```jsx
try {
  // 실행할 코드를 입력
  // 정상이라면 문제없이 실행되지만, 경우에 따라 예외 발생할 수 있음
  const result = someFunction();
} catch (e) {}
```

- 에러가 났을 때 원상복구를 시도할 코드
- 에러 발생시 코드의 실행 흐름이 catch 블록으로 옮겨감

<br>

### 3.2. catch 문

```jsx
try {
  // 예외가 발생할 가능성이 있는 코드
  const result = someFunction();
} catch (e) {
  // 이 블록 내부의 문장들은 오직 try 블록에서 예외가 발생할 경우에만 실행됨
  // 이 문장들에선 지역 변수 e를 사용하여 Error 객체 또는 앞에서 던진 다른 값을 참조 가능
  // 이 블록에서는 어떻게든 그 예외를 처리할 수도 있고, 그냥 아무것도 하지 않고 예외 무시할 수도 있음
}
```

- 에러에 대한 정보를 담고 있는 객체(e 매개변수)를 사용할 수 있음
  - `e.name`: 에러 이름
  - `e.message`: 에러 상세 내용을 담고 있는 문자 메세지
  - `e.stack`: 현재 호출 스택. 에러를 유발한 중첩 호출들의 순서 정보를 가진 문자열로 디버깅 목적으로 사용됨
- try - catch 블록 안의 변수는 함수나 `for` 문 같이 지역 변수로 취급됨

<br>

### 3.3. finally 문

```jsx
try {
  // 예외가 발생할 가능성이 있는 코드
  const result = someFunction();
  console.log(result);
} catch (error) {
  // 예외가 발생했을 때 실행되는 코드
  console.error(error);
} finally {
  // 예외 발생 여부와 상관 없이 실행되는 코드
  console.log("finally block executed");
}
```

- try 블록 안에서는 **에러 발생 여부와 관계 없이 무조건 실행**되어야 하는 코드
- `return`, `break`, `continue` 등으로 코드의 실행 흐름이 즉시 이동되더라도 무조건 실행됨
- 보통 catch와 같이 쓰임
- 에러가 나지 않았을 때: try - finally
- 에러가 났을 때: try - 에러 발생 - catch - finally

<br>

### 3.4. finally 사용 이유

- catch 블록과 finallty 블록은 선택적인 옵션이라 반드시 사용할 필요 X
- BUT! 어떠한 로직에 대해 에러의 유무와 상관없이, 작업 후 초기화를 반드시 해야 하는 경우

  - try - catch 문 뒤에 작업 내역 삭제 로직 실행

    ```jsx
    try {
      작업
    } catch (e) {
      에러 핸들링
    }

    작업 내역 삭제
    ```

    - try 문 안에 작업이 에러가 뜨면 catch에서 핸들링을 하고 스크립트가 종료됨

  - finally 예외처리를 명시함으로써 스크립트 종료되기 전에 반드시 삭제가 실행되도록 지정
    ```jsx
    try {
      작업
    } catch (e) {
      에러 핸들링
    } finally {
      작업 내역 삭제
    }
    ```

<br><br>

## 4. 예외 던지기 (throw)

- 예외를 강제로 발생시켜야 할 경우가 생길 때 `throw` 사용
  - 예외를 발생시킨다 = 에러나 예외 상황을 알린다
- 개발자가 예외를 던지면, 예외 객체가 생성되고, 이 객체는 프로그램 실행 중에 catch 블록에서 처리됨
  - 예시
    - 브라우저 프롬프트 창을 이용해 사용자로부터 숫자를 입력받고, 만일 짝수가 아닐 경우 강제적으로 에러 발생시켜 던짐
      ```jsx
      try {
        const even = parseInt(prompt("짝수를 입력하세요"));
        if (even % 2 !== 0) {
          throw new Error("짝수가 아닙니다.");
        }
      } catch (e) {
        alert(e.message);
      }
      // 3을 입력할 경우
      // Error: 짝수가 아닙니다.
      ```
- 예외를 던질 때 `new Error('에러 메세지')` 와 같이 예외 객체를 생성하여 던짐

<br><br>

## 5. 다중 예외 처리

- 자바스크립트에서는 예외 타입이 명시적으로 되어 있지 않기 때문에 `instanceof` 연산자를 사용하여 조건 분기문을 통해 예외 객체의 타입을 확인하고 구분하여 처리
  ```jsx
  try {
    // ...
  } catch (error) {
    if (error instanceof TypeError) {
      console.error("Caught a TypeError: " + error.message);
    } else if (error instanceof ReferenceError) {
      console.error("Caught a ReferenceError: " + error.message);
    } else if (error instanceof SyntaxError) {
      console.error("Caught a SyntaxError: " + error.message);
    } else if (error instanceof RangeError) {
      console.error("Caught a RangeError: " + error.message);
    } else {
      console.error("Caught an unexpected error: " + error);
    }
  }
  ```
- 혹은 `error.name` 프로퍼티를 통해서 다중 예외 처리 가능
  ```jsx
  try {
    // 에러가 발생할 수 있는 코드
  } catch (error) {
    // 에러 객체를 받아서 처리
    if (error.name === "ReferenceError") {
      // 참조 에러일 경우의 처리
    } else if (error.name === "SyntaxError") {
      // 구문 에러일 경우의 처리
    } else if (error.name === "TypeError") {
      // 타입 에러일 경우의 처리
    } else {
      // 그 외의 에러일 경우의 처리
    }
  }
  ```

<br><br>

## 6. 사용자 정의 예외 만들기

- 자바스크립트에서 커스텀 예외를 만들려면 `Error` 클래스를 상속받아 새로운 클래스 만들어야 함

  ```jsx
  // 사용자 정의 예외 타입
  class MyError extends Error {
    // Error 부모 클래스를 상속한다.
    constructor(message) {
      super(message);
      this.name = "MyError";
    }
  }

  try {
    throw new MyError("Something went wrong");
  } catch (error) {
    // 에러 객체를 받아서 처리
    if (error.name === "MyError") {
      console.log(error.message); // 'Something went wrong'
    }
  }
  ```

  - `Error` 상위 클래스를 상속받아 커스텀 예외 클래스를 만들고 `throw` 키워드를 사용하여 커스텀 예외 객체를 생성하고 던지면 `catch` 블록에서 커스텀 예외 처리 다룰 수 있음

<br><br>

## 7. 예외 처리 Stack 추적

- 스택 프로퍼티를 이용해 서로 함수를 호출하여 얽히고 섥힌 호출 코드 중에 어느 함수 호출에서 에러가 발생했는지 추적 가능
- 예시

  ```jsx
  function a() {
    console.log("a: calling b");
    b();
    console.log("a: done");
  }
  function b() {
    console.log("b: calling c");
    c();
    console.log("b: done");
  }
  function c() {
    console.log("c: throwing error");
    throw new Error("c error");
    console.log("c: done");
  }

  try {
    a();
  } catch (err) {
    console.log(err.stack);
  }
  ```

  - 함수 c가 실행을 마칠 때 실행 흐름은 함수 b로 돌아가고 b가 실행을 마칠 때 실행 흐름은 함수 a로 돌아감
    - c가 실행 중일 때는 a와 b는 완료될 수 없고 이렇게 완료되지 않은 함수가 쌓이는 것을 **Call Stack**이라 부름
  - 자바스크립트 인터프리터는 함수의 호출 과정을 모두 추적하고 있기 때문에, 발생한 에러는 콜 스택 어디에서든 캐치 가능
    - 에러를 캐치하면 콜 스택에서 문제 해결에 유용한 정보 얻을 수 있음
    - 디버그에 유용
